[2021-08-10 18:53:56,911] {taskinstance.py:876} INFO - Dependencies all met for <TaskInstance: Covid.Covidtask1 2021-08-10T13:08:43.680287+00:00 [queued]>
[2021-08-10 18:53:56,918] {taskinstance.py:876} INFO - Dependencies all met for <TaskInstance: Covid.Covidtask1 2021-08-10T13:08:43.680287+00:00 [queued]>
[2021-08-10 18:53:56,918] {taskinstance.py:1067} INFO - 
--------------------------------------------------------------------------------
[2021-08-10 18:53:56,918] {taskinstance.py:1068} INFO - Starting attempt 1 of 8
[2021-08-10 18:53:56,918] {taskinstance.py:1069} INFO - 
--------------------------------------------------------------------------------
[2021-08-10 18:53:57,274] {taskinstance.py:1087} INFO - Executing <Task(PythonOperator): Covidtask1> on 2021-08-10T13:08:43.680287+00:00
[2021-08-10 18:53:57,280] {standard_task_runner.py:52} INFO - Started process 32845 to run task
[2021-08-10 18:53:57,312] {standard_task_runner.py:76} INFO - Running: ['airflow', 'tasks', 'run', 'Covid', 'Covidtask1', '2021-08-10T13:08:43.680287+00:00', '--job-id', '355', '--pool', 'default_pool', '--raw', '--subdir', 'DAGS_FOLDER/dag.py', '--cfg-path', '/tmp/tmp69q10_vd', '--error-file', '/tmp/tmpiludvqfy']
[2021-08-10 18:53:57,314] {standard_task_runner.py:77} INFO - Job 355: Subtask Covidtask1
[2021-08-10 18:53:57,489] {logging_mixin.py:104} INFO - Running <TaskInstance: Covid.Covidtask1 2021-08-10T13:08:43.680287+00:00 [running]> on host deepika-Inspiron-5570
[2021-08-10 18:53:57,782] {taskinstance.py:1280} INFO - Exporting the following env vars:
AIRFLOW_CTX_DAG_EMAIL=sthadpka93@gmail.com
AIRFLOW_CTX_DAG_OWNER=postgres
AIRFLOW_CTX_DAG_ID=Covid
AIRFLOW_CTX_TASK_ID=Covidtask1
AIRFLOW_CTX_EXECUTION_DATE=2021-08-10T13:08:43.680287+00:00
AIRFLOW_CTX_DAG_RUN_ID=manual__2021-08-10T13:08:43.680287+00:00
[2021-08-10 18:53:57,782] {taskinstance.py:1481} ERROR - Task failed with exception
Traceback (most recent call last):
  File "/home/deepika/.local/lib/python3.8/site-packages/airflow/models/taskinstance.py", line 1137, in _run_raw_task
    self._prepare_and_execute_task_with_callbacks(context, task)
  File "/home/deepika/.local/lib/python3.8/site-packages/airflow/models/taskinstance.py", line 1311, in _prepare_and_execute_task_with_callbacks
    result = self._execute_task(context, task_copy)
  File "/home/deepika/.local/lib/python3.8/site-packages/airflow/models/taskinstance.py", line 1341, in _execute_task
    result = task_copy.execute(context=context)
  File "/home/deepika/.local/lib/python3.8/site-packages/airflow/operators/python.py", line 150, in execute
    return_value = self.execute_callable()
  File "/home/deepika/.local/lib/python3.8/site-packages/airflow/operators/python.py", line 161, in execute_callable
    return self.python_callable(*self.op_args, **self.op_kwargs)
  File "/home/deepika/airflow/dags/dag.py", line 10, in fuse_task1
    load_df(task1(), 1)
NameError: name 'load_df' is not defined
[2021-08-10 18:53:57,796] {taskinstance.py:1524} INFO - Marking task as UP_FOR_RETRY. dag_id=Covid, task_id=Covidtask1, execution_date=20210810T130843, start_date=20210810T130856, end_date=20210810T130857
[2021-08-10 18:53:57,942] {local_task_job.py:151} INFO - Task exited with return code 1
